<?xml version="1.0" ?>
<!-- =================================================================================== -->
<!-- |    This document was autogenerated by xacro from snakebot.urdf.xacro            | -->
<!-- |    EDITING THIS FILE BY HAND IS NOT RECOMMENDED                                 | -->
<!-- =================================================================================== -->
<robot name="snakebot">
  <!-- *************************************************** -->
  <!-- ******************* PARAMETERS ******************** -->
  <!-- *************************************************** -->
  <material name="Grey">
    <color rgba="0.4 0.4 0.4 1.0"/>
  </material>
  <material name="Red">
    <color rgba="0.82 0.06 0.06 1.0"/>
  </material>
  <material name="Orange">
    <color rgba="1.0 0.4235294117647059 0.0392156862745098 1.0"/>
  </material>
  <!-- *************************************************** -->
  <!-- ******************** BASE MACRO ******************* -->
  <!-- *************************************************** -->
  <!-- *************************************************** -->
  <!-- *************** PAIR OF JOINTS MACRO ************** -->
  <!-- *************************************************** -->
  <!-- *************************************************** -->
  <!-- ***************** TIP FLANGE MACRO **************** -->
  <!-- *************************************************** -->
  <!-- *************************************************** -->
  <!-- ********************** ROBOT ********************** -->
  <!-- *************************************************** -->
  <link name="world"/>
  <joint name="attach-base" type="fixed">
    <parent link="world"/>
    <child link="link0b"/>
  </joint>
  <link name="link0b">
    <visual>
      <geometry>
        <mesh filename="package://snakebot/meshes/base.stl"/>
      </geometry>
      <material name="Grey"/>
    </visual>
  </link>
  <joint name="shift0" type="fixed">
    <parent link="link0b"/>
    <child link="link0c"/>
    <origin rpy="0 0 0" xyz="0 0 0.1575"/>
  </joint>
  <link name="link0c">
    </link>
  <joint name="joint1a" type="continuous">
    <parent link="link0c"/>
    <child link="link1a"/>
    <origin rpy="0 0 3.141592653589793" xyz="0 0 0"/>
    <axis xyz="0 0 1"/>
  </joint>
  <link name="link1a">
    <inertial>
      <origin rpy="0 0 0" xyz="0 -0.03 0.12"/>
      <mass value="4"/>
      <inertia ixx="0.1" ixy="0" ixz="0" iyy="0.09" iyz="0" izz="0.02"/>
    </inertial>
    <visual>
      <origin rpy="0 0 0" xyz="0 0 0"/>
      <geometry>
        <mesh filename="package://snakebot/meshes/link.stl"/>
      </geometry>
      <material name="Orange"/>
    </visual>
  </link>
  <joint name="joint1b" type="continuous">
    <parent link="link1a"/>
    <child link="link1b"/>
    <origin rpy="0 0 0" xyz="0 0 0.2025"/>
    <axis xyz="0 1 0"/>
  </joint>
  <link name="link1b">
    <inertial>
      <origin rpy="3.141592653589793 0 0" xyz="0 0.03 0.08250000000000002"/>
      <mass value="4"/>
      <inertia ixx="0.1" ixy="0" ixz="0" iyy="0.09" iyz="0" izz="0.02"/>
    </inertial>
    <visual>
      <origin rpy="3.141592653589793 0 0" xyz="0 0 0.2025"/>
      <geometry>
        <mesh filename="package://snakebot/meshes/link.stl"/>
      </geometry>
      <material name="Orange"/>
    </visual>
  </link>
  <joint name="shift1" type="fixed">
    <parent link="link1b"/>
    <child link="link1c"/>
    <origin rpy="0 0 0" xyz="0 0 0.2025"/>
  </joint>
  <link name="link1c">
    </link>
  <joint name="joint2a" type="continuous">
    <parent link="link1c"/>
    <child link="link2a"/>
    <origin rpy="0 0 3.141592653589793" xyz="0 0 0"/>
    <axis xyz="0 0 1"/>
  </joint>
  <link name="link2a">
    <inertial>
      <origin rpy="0 0 0" xyz="0 -0.03 0.12"/>
      <mass value="4"/>
      <inertia ixx="0.1" ixy="0" ixz="0" iyy="0.09" iyz="0" izz="0.02"/>
    </inertial>
    <visual>
      <origin rpy="0 0 0" xyz="0 0 0"/>
      <geometry>
        <mesh filename="package://snakebot/meshes/link.stl"/>
      </geometry>
      <material name="Orange"/>
    </visual>
  </link>
  <joint name="joint2b" type="continuous">
    <parent link="link2a"/>
    <child link="link2b"/>
    <origin rpy="0 0 0" xyz="0 0 0.2025"/>
    <axis xyz="0 1 0"/>
  </joint>
  <link name="link2b">
    <inertial>
      <origin rpy="3.141592653589793 0 0" xyz="0 0.03 0.08250000000000002"/>
      <mass value="4"/>
      <inertia ixx="0.1" ixy="0" ixz="0" iyy="0.09" iyz="0" izz="0.02"/>
    </inertial>
    <visual>
      <origin rpy="3.141592653589793 0 0" xyz="0 0 0.2025"/>
      <geometry>
        <mesh filename="package://snakebot/meshes/link.stl"/>
      </geometry>
      <material name="Orange"/>
    </visual>
  </link>
  <joint name="shift2" type="fixed">
    <parent link="link2b"/>
    <child link="link2c"/>
    <origin rpy="0 0 0" xyz="0 0 0.2025"/>
  </joint>
  <link name="link2c">
    </link>
  <joint name="joint3a" type="continuous">
    <parent link="link2c"/>
    <child link="link3a"/>
    <origin rpy="0 0 3.141592653589793" xyz="0 0 0"/>
    <axis xyz="0 0 1"/>
  </joint>
  <link name="link3a">
    <inertial>
      <origin rpy="0 0 0" xyz="0 -0.03 0.12"/>
      <mass value="4"/>
      <inertia ixx="0.1" ixy="0" ixz="0" iyy="0.09" iyz="0" izz="0.02"/>
    </inertial>
    <visual>
      <origin rpy="0 0 0" xyz="0 0 0"/>
      <geometry>
        <mesh filename="package://snakebot/meshes/link.stl"/>
      </geometry>
      <material name="Orange"/>
    </visual>
  </link>
  <joint name="joint3b" type="continuous">
    <parent link="link3a"/>
    <child link="link3b"/>
    <origin rpy="0 0 0" xyz="0 0 0.2025"/>
    <axis xyz="0 1 0"/>
  </joint>
  <link name="link3b">
    <inertial>
      <origin rpy="3.141592653589793 0 0" xyz="0 0.03 0.08250000000000002"/>
      <mass value="4"/>
      <inertia ixx="0.1" ixy="0" ixz="0" iyy="0.09" iyz="0" izz="0.02"/>
    </inertial>
    <visual>
      <origin rpy="3.141592653589793 0 0" xyz="0 0 0.2025"/>
      <geometry>
        <mesh filename="package://snakebot/meshes/link.stl"/>
      </geometry>
      <material name="Orange"/>
    </visual>
  </link>
  <joint name="shift3" type="fixed">
    <parent link="link3b"/>
    <child link="link3c"/>
    <origin rpy="0 0 0" xyz="0 0 0.2025"/>
  </joint>
  <link name="link3c">
    </link>
  <joint name="joint4a" type="continuous">
    <parent link="link3c"/>
    <child link="link4a"/>
    <origin rpy="0 0 3.141592653589793" xyz="0 0 0"/>
    <axis xyz="0 0 1"/>
  </joint>
  <link name="link4a">
    <inertial>
      <origin rpy="0 0 0" xyz="0 -0.03 0.12"/>
      <mass value="4"/>
      <inertia ixx="0.1" ixy="0" ixz="0" iyy="0.09" iyz="0" izz="0.02"/>
    </inertial>
    <visual>
      <origin rpy="0 0 0" xyz="0 0 0"/>
      <geometry>
        <mesh filename="package://snakebot/meshes/link.stl"/>
      </geometry>
      <material name="Orange"/>
    </visual>
  </link>
  <joint name="joint4b" type="continuous">
    <parent link="link4a"/>
    <child link="link4b"/>
    <origin rpy="0 0 0" xyz="0 0 0.2025"/>
    <axis xyz="0 1 0"/>
  </joint>
  <link name="link4b">
    <inertial>
      <origin rpy="3.141592653589793 0 0" xyz="0 0.03 0.08250000000000002"/>
      <mass value="4"/>
      <inertia ixx="0.1" ixy="0" ixz="0" iyy="0.09" iyz="0" izz="0.02"/>
    </inertial>
    <visual>
      <origin rpy="3.141592653589793 0 0" xyz="0 0 0.2025"/>
      <geometry>
        <mesh filename="package://snakebot/meshes/link.stl"/>
      </geometry>
      <material name="Orange"/>
    </visual>
  </link>
  <joint name="shift4" type="fixed">
    <parent link="link4b"/>
    <child link="link4c"/>
    <origin rpy="0 0 0" xyz="0 0 0.2025"/>
  </joint>
  <link name="link4c">
    </link>
  <joint name="joint5a" type="continuous">
    <parent link="link4c"/>
    <child link="link5a"/>
    <origin rpy="0 0 3.141592653589793" xyz="0 0 0"/>
    <axis xyz="0 0 1"/>
  </joint>
  <link name="link5a">
    <inertial>
      <origin rpy="0 0 0" xyz="0 -0.03 0.12"/>
      <mass value="4"/>
      <inertia ixx="0.1" ixy="0" ixz="0" iyy="0.09" iyz="0" izz="0.02"/>
    </inertial>
    <visual>
      <origin rpy="0 0 0" xyz="0 0 0"/>
      <geometry>
        <mesh filename="package://snakebot/meshes/link.stl"/>
      </geometry>
      <material name="Orange"/>
    </visual>
  </link>
  <joint name="joint5b" type="continuous">
    <parent link="link5a"/>
    <child link="link5b"/>
    <origin rpy="0 0 0" xyz="0 0 0.2025"/>
    <axis xyz="0 1 0"/>
  </joint>
  <link name="link5b">
    <inertial>
      <origin rpy="3.141592653589793 0 0" xyz="0 0.03 0.08250000000000002"/>
      <mass value="4"/>
      <inertia ixx="0.1" ixy="0" ixz="0" iyy="0.09" iyz="0" izz="0.02"/>
    </inertial>
    <visual>
      <origin rpy="3.141592653589793 0 0" xyz="0 0 0.2025"/>
      <geometry>
        <mesh filename="package://snakebot/meshes/link.stl"/>
      </geometry>
      <material name="Orange"/>
    </visual>
  </link>
  <joint name="shift5" type="fixed">
    <parent link="link5b"/>
    <child link="link5c"/>
    <origin rpy="0 0 0" xyz="0 0 0.2025"/>
  </joint>
  <link name="link5c">
    </link>
  <joint name="joint6a" type="continuous">
    <parent link="link5c"/>
    <child link="link6a"/>
    <origin rpy="0 0 3.141592653589793" xyz="0 0 0"/>
    <axis xyz="0 0 1"/>
  </joint>
  <link name="link6a">
    <inertial>
      <origin rpy="0 0 0" xyz="0 -0.03 0.12"/>
      <mass value="4"/>
      <inertia ixx="0.1" ixy="0" ixz="0" iyy="0.09" iyz="0" izz="0.02"/>
    </inertial>
    <visual>
      <origin rpy="0 0 0" xyz="0 0 0"/>
      <geometry>
        <mesh filename="package://snakebot/meshes/link.stl"/>
      </geometry>
      <material name="Orange"/>
    </visual>
  </link>
  <joint name="joint6b" type="continuous">
    <parent link="link6a"/>
    <child link="link6b"/>
    <origin rpy="0 0 0" xyz="0 0 0.2025"/>
    <axis xyz="0 1 0"/>
  </joint>
  <link name="link6b">
    <inertial>
      <origin rpy="3.141592653589793 0 0" xyz="0 0.03 0.08250000000000002"/>
      <mass value="4"/>
      <inertia ixx="0.1" ixy="0" ixz="0" iyy="0.09" iyz="0" izz="0.02"/>
    </inertial>
    <visual>
      <origin rpy="3.141592653589793 0 0" xyz="0 0 0.2025"/>
      <geometry>
        <mesh filename="package://snakebot/meshes/link.stl"/>
      </geometry>
      <material name="Orange"/>
    </visual>
  </link>
  <joint name="shift6" type="fixed">
    <parent link="link6b"/>
    <child link="link6c"/>
    <origin rpy="0 0 0" xyz="0 0 0.2025"/>
  </joint>
  <link name="link6c">
    </link>
  <joint name="joint7a" type="continuous">
    <parent link="link6c"/>
    <child link="link7a"/>
    <origin rpy="0 0 3.141592653589793" xyz="0 0 0"/>
    <axis xyz="0 0 1"/>
  </joint>
  <link name="link7a">
    <inertial>
      <origin rpy="0 0 0" xyz="0 -0.03 0.12"/>
      <mass value="4"/>
      <inertia ixx="0.1" ixy="0" ixz="0" iyy="0.09" iyz="0" izz="0.02"/>
    </inertial>
    <visual>
      <origin rpy="0 0 0" xyz="0 0 0"/>
      <geometry>
        <mesh filename="package://snakebot/meshes/link.stl"/>
      </geometry>
      <material name="Orange"/>
    </visual>
  </link>
  <joint name="joint7b" type="continuous">
    <parent link="link7a"/>
    <child link="link7b"/>
    <origin rpy="0 0 0" xyz="0 0 0.2025"/>
    <axis xyz="0 1 0"/>
  </joint>
  <link name="link7b">
    <inertial>
      <origin rpy="3.141592653589793 0 0" xyz="0 0.03 0.08250000000000002"/>
      <mass value="4"/>
      <inertia ixx="0.1" ixy="0" ixz="0" iyy="0.09" iyz="0" izz="0.02"/>
    </inertial>
    <visual>
      <origin rpy="3.141592653589793 0 0" xyz="0 0 0.2025"/>
      <geometry>
        <mesh filename="package://snakebot/meshes/link.stl"/>
      </geometry>
      <material name="Orange"/>
    </visual>
  </link>
  <joint name="shift7" type="fixed">
    <parent link="link7b"/>
    <child link="link7c"/>
    <origin rpy="0 0 0" xyz="0 0 0.2025"/>
  </joint>
  <link name="link7c">
    </link>
  <joint name="joint8a" type="continuous">
    <parent link="link7c"/>
    <child link="link8a"/>
    <origin rpy="0 0 3.141592653589793" xyz="0 0 0"/>
    <axis xyz="0 0 1"/>
  </joint>
  <link name="link8a">
    <inertial>
      <origin rpy="0 0 0" xyz="0 -0.03 0.12"/>
      <mass value="4"/>
      <inertia ixx="0.1" ixy="0" ixz="0" iyy="0.09" iyz="0" izz="0.02"/>
    </inertial>
    <visual>
      <origin rpy="0 0 0" xyz="0 0 0"/>
      <geometry>
        <mesh filename="package://snakebot/meshes/link.stl"/>
      </geometry>
      <material name="Orange"/>
    </visual>
  </link>
  <joint name="joint8b" type="continuous">
    <parent link="link8a"/>
    <child link="link8b"/>
    <origin rpy="0 0 0" xyz="0 0 0.2025"/>
    <axis xyz="0 1 0"/>
  </joint>
  <link name="link8b">
    <inertial>
      <origin rpy="3.141592653589793 0 0" xyz="0 0.03 0.08250000000000002"/>
      <mass value="4"/>
      <inertia ixx="0.1" ixy="0" ixz="0" iyy="0.09" iyz="0" izz="0.02"/>
    </inertial>
    <visual>
      <origin rpy="3.141592653589793 0 0" xyz="0 0 0.2025"/>
      <geometry>
        <mesh filename="package://snakebot/meshes/link.stl"/>
      </geometry>
      <material name="Orange"/>
    </visual>
  </link>
  <joint name="shift8" type="fixed">
    <parent link="link8b"/>
    <child link="link8c"/>
    <origin rpy="0 0 0" xyz="0 0 0.2025"/>
  </joint>
  <link name="link8c">
    </link>
  <joint name="attach-mating-plate" type="fixed">
    <parent link="link8c"/>
    <child link="mating-plate"/>
  </joint>
  <link name="mating-plate">
    <visual>
      <geometry>
        <cylinder length="0.001" radius="0.086"/>
      </geometry>
      <material name="Grey"/>
    </visual>
  </link>
  <joint name="attach-flange" type="fixed">
    <parent link="mating-plate"/>
    <child link="flange"/>
  </joint>
  <link name="flange">
    <inertial>
      <origin rpy="0 0 0" xyz="0 0 0.02"/>
      <mass value="0.42857142857142855"/>
      <!--this is for the MFT Pneumatisch flange-->
      <inertia ixx="0.01" ixy="0" ixz="0" iyy="0.01" iyz="0" izz="0.01"/>
    </inertial>
    <visual>
      <geometry>
        <mesh filename="package://snakebot/meshes/flange.stl"/>
      </geometry>
      <material name="Grey"/>
    </visual>
  </link>
  <joint name="finalspin" type="continuous">
    <parent link="flange"/>
    <child link="tip"/>
    <origin rpy="0 0 0" xyz="0 0 0.045"/>
    <axis xyz="0 0 1"/>
  </joint>
  <link name="tip"/>
</robot>

